<?xml version="1.0" encoding="UTF-8"?>
<testsuite errors="1" failures="0" file="Apps/PropertyManagers/test_models.py" name="Apps.PropertyManagers.test_models.TestUser-20200303214930" skipped="0" tests="1" time="0.000" timestamp="0001-01-01T00:00:00">
	<testcase classname="Apps.PropertyManagers.test_models.TestUser" name="test_str" time="0.000" timestamp="0001-01-01T00:00:00">
		<error message="create_user() missing 1 required positional argument: 'username'" type="TypeError">
<![CDATA[Traceback (most recent call last):
  File "/Applications/Xcode.app/Contents/Developer/Library/Frameworks/Python3.framework/Versions/3.7/lib/python3.7/unittest/suite.py", line 163, in _handleClassSetUp
    setUpClass()
  File "/Users/aberard/Programming/HomePairs/django_env/lib/python3.7/site-packages/django/test/testcases.py", line 1137, in setUpClass
    cls.setUpTestData()
  File "/Users/aberard/Programming/HomePairs/2.0/homepairs/HomepairsApp/Apps/PropertyManagers/test_models.py", line 9, in setUpTestData
    cls.user = get_user_model().objects.create_user(email="test@test.com", first_name="Test", last_name="User")
TypeError: create_user() missing 1 required positional argument: 'username'
]]>		</error>
		<system-out>
<![CDATA[]]>		</system-out>
		<system-err>
<![CDATA[]]>		</system-err>
	</testcase>
</testsuite>
